[2024-11-14T19:09:44.475+0000] {local_task_job_runner.py:120} INFO - ::group::Pre task execution logs
[2024-11-14T19:09:44.515+0000] {taskinstance.py:2076} INFO - Dependencies all met for dep_context=non-requeueable deps ti=<TaskInstance: BuildELT_dbt.dbt_snapshot manual__2024-11-14T05:38:03.212660+00:00 [queued]>
[2024-11-14T19:09:44.528+0000] {taskinstance.py:2076} INFO - Dependencies all met for dep_context=requeueable deps ti=<TaskInstance: BuildELT_dbt.dbt_snapshot manual__2024-11-14T05:38:03.212660+00:00 [queued]>
[2024-11-14T19:09:44.529+0000] {taskinstance.py:2306} INFO - Starting attempt 1 of 1
[2024-11-14T19:09:44.551+0000] {taskinstance.py:2330} INFO - Executing <Task(BashOperator): dbt_snapshot> on 2024-11-14 05:38:03.212660+00:00
[2024-11-14T19:09:44.565+0000] {standard_task_runner.py:90} INFO - Running: ['***', 'tasks', 'run', 'BuildELT_dbt', 'dbt_snapshot', 'manual__2024-11-14T05:38:03.212660+00:00', '--job-id', '178', '--raw', '--subdir', 'DAGS_FOLDER/build_elt_with_dbt.py', '--cfg-path', '/tmp/tmptgntotc4']
[2024-11-14T19:09:44.600+0000] {standard_task_runner.py:91} INFO - Job 178: Subtask dbt_snapshot
[2024-11-14T19:09:44.605+0000] {logging_mixin.py:188} WARNING - /home/***/.local/lib/python3.12/site-packages/***/task/task_runner/standard_task_runner.py:61 DeprecationWarning: This process (pid=20963) is multi-threaded, use of fork() may lead to deadlocks in the child.
[2024-11-14T19:09:44.614+0000] {standard_task_runner.py:63} INFO - Started process 20968 to run task
[2024-11-14T19:09:45.109+0000] {task_command.py:426} INFO - Running <TaskInstance: BuildELT_dbt.dbt_snapshot manual__2024-11-14T05:38:03.212660+00:00 [running]> on host 5c9ef59c8996
[2024-11-14T19:09:45.552+0000] {taskinstance.py:2648} INFO - Exporting env vars: AIRFLOW_CTX_DAG_OWNER='***' AIRFLOW_CTX_DAG_ID='BuildELT_dbt' AIRFLOW_CTX_TASK_ID='dbt_snapshot' AIRFLOW_CTX_EXECUTION_DATE='2024-11-14T05:38:03.212660+00:00' AIRFLOW_CTX_TRY_NUMBER='1' AIRFLOW_CTX_DAG_RUN_ID='manual__2024-11-14T05:38:03.212660+00:00'
[2024-11-14T19:09:45.554+0000] {taskinstance.py:430} INFO - ::endgroup::
[2024-11-14T19:09:45.577+0000] {subprocess.py:63} INFO - Tmp dir root location: /tmp
[2024-11-14T19:09:45.580+0000] {subprocess.py:75} INFO - Running command: ['/usr/bin/bash', '-c', '/home/***/.local/bin/dbt snapshot --profiles-dir /opt/***/dbt --project-dir /opt/***/dbt']
[2024-11-14T19:09:45.593+0000] {subprocess.py:86} INFO - Output:
[2024-11-14T19:09:48.335+0000] {subprocess.py:93} INFO - [0m19:09:48  Running with dbt=1.8.7
[2024-11-14T19:09:50.208+0000] {subprocess.py:93} INFO - [0m19:09:50  Registered adapter: snowflake=1.8.4
[2024-11-14T19:09:50.800+0000] {subprocess.py:93} INFO - [0m19:09:50  Found 2 models, 1 snapshot, 5 data tests, 1 source, 459 macros
[2024-11-14T19:09:50.807+0000] {subprocess.py:93} INFO - [0m19:09:50
[2024-11-14T19:09:52.761+0000] {subprocess.py:93} INFO - [0m19:09:52  Concurrency: 1 threads (target='dev')
[2024-11-14T19:09:52.767+0000] {subprocess.py:93} INFO - [0m19:09:52
[2024-11-14T19:09:52.880+0000] {subprocess.py:93} INFO - [0m19:09:52  1 of 1 START snapshot raw_data.raw_data_snapshot ............................... [RUN]
[2024-11-14T19:09:56.762+0000] {subprocess.py:93} INFO - [0m19:09:56  1 of 1 ERROR snapshotting raw_data.raw_data_snapshot ........................... [[31mERROR[0m in 3.87s]
[2024-11-14T19:09:56.772+0000] {subprocess.py:93} INFO - [0m19:09:56
[2024-11-14T19:09:56.773+0000] {subprocess.py:93} INFO - [0m19:09:56  Finished running 1 snapshot in 0 hours 0 minutes and 5.96 seconds (5.96s).
[2024-11-14T19:09:56.848+0000] {subprocess.py:93} INFO - [0m19:09:56
[2024-11-14T19:09:56.850+0000] {subprocess.py:93} INFO - [0m19:09:56  [31mCompleted with 1 error and 0 warnings:[0m
[2024-11-14T19:09:56.851+0000] {subprocess.py:93} INFO - [0m19:09:56
[2024-11-14T19:09:56.853+0000] {subprocess.py:93} INFO - [0m19:09:56    Database Error in snapshot raw_data_snapshot (snapshots/raw_data_snapshot.sql)
[2024-11-14T19:09:56.854+0000] {subprocess.py:93} INFO -   100090 (42P18): Duplicate row detected during DML action
[2024-11-14T19:09:56.855+0000] {subprocess.py:93} INFO -   Row Values: [redacted]
[2024-11-14T19:09:56.856+0000] {subprocess.py:93} INFO -   compiled code at target/run/stock_dbt/snapshots/raw_data_snapshot.sql
[2024-11-14T19:09:56.856+0000] {subprocess.py:93} INFO - [0m19:09:56
[2024-11-14T19:09:56.858+0000] {subprocess.py:93} INFO - [0m19:09:56  Done. PASS=0 WARN=0 ERROR=1 SKIP=0 TOTAL=1
[2024-11-14T19:09:58.081+0000] {subprocess.py:97} INFO - Command exited with return code 1
[2024-11-14T19:09:58.082+0000] {taskinstance.py:441} INFO - ::group::Post task execution logs
[2024-11-14T19:09:58.097+0000] {taskinstance.py:2905} ERROR - Task failed with exception
Traceback (most recent call last):
  File "/home/airflow/.local/lib/python3.12/site-packages/airflow/models/taskinstance.py", line 465, in _execute_task
    result = _execute_callable(context=context, **execute_callable_kwargs)
             ^^^^^^^^^^^^^^^^^^^^^^^^^^^^^^^^^^^^^^^^^^^^^^^^^^^^^^^^^^^^^
  File "/home/airflow/.local/lib/python3.12/site-packages/airflow/models/taskinstance.py", line 432, in _execute_callable
    return execute_callable(context=context, **execute_callable_kwargs)
           ^^^^^^^^^^^^^^^^^^^^^^^^^^^^^^^^^^^^^^^^^^^^^^^^^^^^^^^^^^^^
  File "/home/airflow/.local/lib/python3.12/site-packages/airflow/models/baseoperator.py", line 400, in wrapper
    return func(self, *args, **kwargs)
           ^^^^^^^^^^^^^^^^^^^^^^^^^^^
  File "/home/airflow/.local/lib/python3.12/site-packages/airflow/operators/bash.py", line 243, in execute
    raise AirflowException(
airflow.exceptions.AirflowException: Bash command failed. The command returned a non-zero exit code 1.
[2024-11-14T19:09:58.140+0000] {taskinstance.py:1206} INFO - Marking task as FAILED. dag_id=BuildELT_dbt, task_id=dbt_snapshot, run_id=manual__2024-11-14T05:38:03.212660+00:00, execution_date=20241114T053803, start_date=20241114T190944, end_date=20241114T190958
[2024-11-14T19:09:58.179+0000] {standard_task_runner.py:110} ERROR - Failed to execute job 178 for task dbt_snapshot (Bash command failed. The command returned a non-zero exit code 1.; 20968)
[2024-11-14T19:09:58.214+0000] {local_task_job_runner.py:240} INFO - Task exited with return code 1
[2024-11-14T19:09:58.245+0000] {taskinstance.py:3498} INFO - 0 downstream tasks scheduled from follow-on schedule check
[2024-11-14T19:09:58.250+0000] {local_task_job_runner.py:222} INFO - ::endgroup::
